[2024-02-07T15:19:01.205+0000] {taskinstance.py:1956} INFO - Dependencies all met for dep_context=non-requeueable deps ti=<TaskInstance: airflow-postgres-dag.query_and_return_value manual__2024-02-07T15:15:49.542144+00:00 [queued]>
[2024-02-07T15:19:01.225+0000] {taskinstance.py:1956} INFO - Dependencies all met for dep_context=requeueable deps ti=<TaskInstance: airflow-postgres-dag.query_and_return_value manual__2024-02-07T15:15:49.542144+00:00 [queued]>
[2024-02-07T15:19:01.229+0000] {taskinstance.py:2170} INFO - Starting attempt 2 of 2
[2024-02-07T15:19:01.254+0000] {taskinstance.py:2191} INFO - Executing <Task(PythonOperator): query_and_return_value> on 2024-02-07 15:15:49.542144+00:00
[2024-02-07T15:19:01.264+0000] {standard_task_runner.py:60} INFO - Started process 6860 to run task
[2024-02-07T15:19:01.273+0000] {standard_task_runner.py:87} INFO - Running: ['***', 'tasks', 'run', '***-postgres-dag', 'query_and_return_value', 'manual__2024-02-07T15:15:49.542144+00:00', '--job-id', '269', '--raw', '--subdir', 'DAGS_FOLDER/election_dag.py', '--cfg-path', '/tmp/tmp8on2w0dw']
[2024-02-07T15:19:01.276+0000] {standard_task_runner.py:88} INFO - Job 269: Subtask query_and_return_value
[2024-02-07T15:19:01.607+0000] {task_command.py:423} INFO - Running <TaskInstance: airflow-postgres-dag.query_and_return_value manual__2024-02-07T15:15:49.542144+00:00 [running]> on host 4775ae97916b
[2024-02-07T15:19:01.841+0000] {taskinstance.py:2480} INFO - Exporting env vars: AIRFLOW_CTX_DAG_OWNER='El_mboup' AIRFLOW_CTX_DAG_ID='***-postgres-dag' AIRFLOW_CTX_TASK_ID='query_and_return_value' AIRFLOW_CTX_EXECUTION_DATE='2024-02-07T15:15:49.542144+00:00' AIRFLOW_CTX_TRY_NUMBER='2' AIRFLOW_CTX_DAG_RUN_ID='manual__2024-02-07T15:15:49.542144+00:00'
[2024-02-07T15:19:01.862+0000] {taskinstance.py:2698} ERROR - Task failed with exception
Traceback (most recent call last):
  File "/home/airflow/.local/lib/python3.8/site-packages/sqlalchemy/engine/base.py", line 1910, in _execute_context
    self.dialect.do_execute(
  File "/home/airflow/.local/lib/python3.8/site-packages/sqlalchemy/engine/default.py", line 736, in do_execute
    cursor.execute(statement, parameters)
psycopg2.errors.UndefinedColumn: column "timestamp" of relation "result_table" does not exist
LINE 1: ...RT INTO result_table (validated_candidates_count, timestamp)...
                                                             ^


The above exception was the direct cause of the following exception:

Traceback (most recent call last):
  File "/home/airflow/.local/lib/python3.8/site-packages/airflow/models/taskinstance.py", line 433, in _execute_task
    result = execute_callable(context=context, **execute_callable_kwargs)
  File "/home/airflow/.local/lib/python3.8/site-packages/airflow/operators/python.py", line 199, in execute
    return_value = self.execute_callable()
  File "/home/airflow/.local/lib/python3.8/site-packages/airflow/operators/python.py", line 216, in execute_callable
    return self.python_callable(*self.op_args, **self.op_kwargs)
  File "/opt/airflow/dags/election_dag.py", line 97, in query_table_and_store_value
    engine.execute("INSERT INTO result_table (validated_candidates_count, timestamp) VALUES (%s, %s);", result, current_timestamp)
  File "<string>", line 2, in execute
  File "/home/airflow/.local/lib/python3.8/site-packages/sqlalchemy/util/deprecations.py", line 468, in warned
    return fn(*args, **kwargs)
  File "/home/airflow/.local/lib/python3.8/site-packages/sqlalchemy/engine/base.py", line 3267, in execute
    return connection.execute(statement, *multiparams, **params)
  File "/home/airflow/.local/lib/python3.8/site-packages/sqlalchemy/engine/base.py", line 1370, in execute
    return self._exec_driver_sql(
  File "/home/airflow/.local/lib/python3.8/site-packages/sqlalchemy/engine/base.py", line 1674, in _exec_driver_sql
    ret = self._execute_context(
  File "/home/airflow/.local/lib/python3.8/site-packages/sqlalchemy/engine/base.py", line 1953, in _execute_context
    self._handle_dbapi_exception(
  File "/home/airflow/.local/lib/python3.8/site-packages/sqlalchemy/engine/base.py", line 2134, in _handle_dbapi_exception
    util.raise_(
  File "/home/airflow/.local/lib/python3.8/site-packages/sqlalchemy/util/compat.py", line 211, in raise_
    raise exception
  File "/home/airflow/.local/lib/python3.8/site-packages/sqlalchemy/engine/base.py", line 1910, in _execute_context
    self.dialect.do_execute(
  File "/home/airflow/.local/lib/python3.8/site-packages/sqlalchemy/engine/default.py", line 736, in do_execute
    cursor.execute(statement, parameters)
sqlalchemy.exc.ProgrammingError: (psycopg2.errors.UndefinedColumn) column "timestamp" of relation "result_table" does not exist
LINE 1: ...RT INTO result_table (validated_candidates_count, timestamp)...
                                                             ^

[SQL: INSERT INTO result_table (validated_candidates_count, timestamp) VALUES (%s, %s);]
[parameters: (3, '2024-02-07 15:19:01')]
(Background on this error at: https://sqlalche.me/e/14/f405)
[2024-02-07T15:19:01.875+0000] {taskinstance.py:1138} INFO - Marking task as FAILED. dag_id=***-postgres-dag, task_id=query_and_return_value, execution_date=20240207T151549, start_date=20240207T151901, end_date=20240207T151901
[2024-02-07T15:19:01.896+0000] {standard_task_runner.py:107} ERROR - Failed to execute job 269 for task query_and_return_value ((psycopg2.errors.UndefinedColumn) column "timestamp" of relation "result_table" does not exist
LINE 1: ...RT INTO result_table (validated_candidates_count, timestamp)...
                                                             ^

[SQL: INSERT INTO result_table (validated_candidates_count, timestamp) VALUES (%s, %s);]
[parameters: (3, '2024-02-07 15:19:01')]
(Background on this error at: https://sqlalche.me/e/14/f405); 6860)
[2024-02-07T15:19:01.941+0000] {local_task_job_runner.py:234} INFO - Task exited with return code 1
[2024-02-07T15:19:01.983+0000] {taskinstance.py:3280} INFO - 0 downstream tasks scheduled from follow-on schedule check
