[2024-02-07T15:24:51.063+0000] {taskinstance.py:1956} INFO - Dependencies all met for dep_context=non-requeueable deps ti=<TaskInstance: airflow-postgres-dag.query_and_return_value manual__2024-02-07T15:15:49.542144+00:00 [queued]>
[2024-02-07T15:24:51.074+0000] {taskinstance.py:1956} INFO - Dependencies all met for dep_context=requeueable deps ti=<TaskInstance: airflow-postgres-dag.query_and_return_value manual__2024-02-07T15:15:49.542144+00:00 [queued]>
[2024-02-07T15:24:51.074+0000] {taskinstance.py:2170} INFO - Starting attempt 4 of 5
[2024-02-07T15:24:51.098+0000] {taskinstance.py:2191} INFO - Executing <Task(PythonOperator): query_and_return_value> on 2024-02-07 15:15:49.542144+00:00
[2024-02-07T15:24:51.110+0000] {standard_task_runner.py:60} INFO - Started process 6955 to run task
[2024-02-07T15:24:51.118+0000] {standard_task_runner.py:87} INFO - Running: ['***', 'tasks', 'run', '***-postgres-dag', 'query_and_return_value', 'manual__2024-02-07T15:15:49.542144+00:00', '--job-id', '271', '--raw', '--subdir', 'DAGS_FOLDER/election_dag.py', '--cfg-path', '/tmp/tmpvomp51zy']
[2024-02-07T15:24:51.120+0000] {standard_task_runner.py:88} INFO - Job 271: Subtask query_and_return_value
[2024-02-07T15:24:51.185+0000] {task_command.py:423} INFO - Running <TaskInstance: airflow-postgres-dag.query_and_return_value manual__2024-02-07T15:15:49.542144+00:00 [running]> on host 4775ae97916b
[2024-02-07T15:24:51.279+0000] {taskinstance.py:2480} INFO - Exporting env vars: AIRFLOW_CTX_DAG_OWNER='El_mboup' AIRFLOW_CTX_DAG_ID='***-postgres-dag' AIRFLOW_CTX_TASK_ID='query_and_return_value' AIRFLOW_CTX_EXECUTION_DATE='2024-02-07T15:15:49.542144+00:00' AIRFLOW_CTX_TRY_NUMBER='4' AIRFLOW_CTX_DAG_RUN_ID='manual__2024-02-07T15:15:49.542144+00:00'
[2024-02-07T15:24:51.292+0000] {taskinstance.py:2698} ERROR - Task failed with exception
Traceback (most recent call last):
  File "/home/airflow/.local/lib/python3.8/site-packages/sqlalchemy/engine/base.py", line 1910, in _execute_context
    self.dialect.do_execute(
  File "/home/airflow/.local/lib/python3.8/site-packages/sqlalchemy/engine/default.py", line 736, in do_execute
    cursor.execute(statement, parameters)
psycopg2.errors.UndefinedColumn: column "timestamp" of relation "result_table" does not exist
LINE 2: ...RT INTO result_table (validated_candidates_count, timestamp)
                                                             ^


The above exception was the direct cause of the following exception:

Traceback (most recent call last):
  File "/home/airflow/.local/lib/python3.8/site-packages/airflow/models/taskinstance.py", line 433, in _execute_task
    result = execute_callable(context=context, **execute_callable_kwargs)
  File "/home/airflow/.local/lib/python3.8/site-packages/airflow/operators/python.py", line 199, in execute
    return_value = self.execute_callable()
  File "/home/airflow/.local/lib/python3.8/site-packages/airflow/operators/python.py", line 216, in execute_callable
    return self.python_callable(*self.op_args, **self.op_kwargs)
  File "/opt/airflow/dags/election_dag.py", line 104, in query_table_and_store_value
    engine.execute(text("""
  File "<string>", line 2, in execute
  File "/home/airflow/.local/lib/python3.8/site-packages/sqlalchemy/util/deprecations.py", line 468, in warned
    return fn(*args, **kwargs)
  File "/home/airflow/.local/lib/python3.8/site-packages/sqlalchemy/engine/base.py", line 3267, in execute
    return connection.execute(statement, *multiparams, **params)
  File "/home/airflow/.local/lib/python3.8/site-packages/sqlalchemy/engine/base.py", line 1385, in execute
    return meth(self, multiparams, params, _EMPTY_EXECUTION_OPTS)
  File "/home/airflow/.local/lib/python3.8/site-packages/sqlalchemy/sql/elements.py", line 334, in _execute_on_connection
    return connection._execute_clauseelement(
  File "/home/airflow/.local/lib/python3.8/site-packages/sqlalchemy/engine/base.py", line 1577, in _execute_clauseelement
    ret = self._execute_context(
  File "/home/airflow/.local/lib/python3.8/site-packages/sqlalchemy/engine/base.py", line 1953, in _execute_context
    self._handle_dbapi_exception(
  File "/home/airflow/.local/lib/python3.8/site-packages/sqlalchemy/engine/base.py", line 2134, in _handle_dbapi_exception
    util.raise_(
  File "/home/airflow/.local/lib/python3.8/site-packages/sqlalchemy/util/compat.py", line 211, in raise_
    raise exception
  File "/home/airflow/.local/lib/python3.8/site-packages/sqlalchemy/engine/base.py", line 1910, in _execute_context
    self.dialect.do_execute(
  File "/home/airflow/.local/lib/python3.8/site-packages/sqlalchemy/engine/default.py", line 736, in do_execute
    cursor.execute(statement, parameters)
sqlalchemy.exc.ProgrammingError: (psycopg2.errors.UndefinedColumn) column "timestamp" of relation "result_table" does not exist
LINE 2: ...RT INTO result_table (validated_candidates_count, timestamp)
                                                             ^

[SQL: 
        INSERT INTO result_table (validated_candidates_count, timestamp)
        VALUES (%(result)s, %(timestamp)s);
    ]
[parameters: {'result': 3, 'timestamp': '2024-02-07 15:24:51'}]
(Background on this error at: https://sqlalche.me/e/14/f405)
[2024-02-07T15:24:51.312+0000] {taskinstance.py:1138} INFO - Marking task as UP_FOR_RETRY. dag_id=***-postgres-dag, task_id=query_and_return_value, execution_date=20240207T151549, start_date=20240207T152451, end_date=20240207T152451
[2024-02-07T15:24:51.325+0000] {standard_task_runner.py:107} ERROR - Failed to execute job 271 for task query_and_return_value ((psycopg2.errors.UndefinedColumn) column "timestamp" of relation "result_table" does not exist
LINE 2: ...RT INTO result_table (validated_candidates_count, timestamp)
                                                             ^

[SQL: 
        INSERT INTO result_table (validated_candidates_count, timestamp)
        VALUES (%(result)s, %(timestamp)s);
    ]
[parameters: {'result': 3, 'timestamp': '2024-02-07 15:24:51'}]
(Background on this error at: https://sqlalche.me/e/14/f405); 6955)
[2024-02-07T15:24:51.339+0000] {local_task_job_runner.py:234} INFO - Task exited with return code 1
[2024-02-07T15:24:51.366+0000] {taskinstance.py:3280} INFO - 0 downstream tasks scheduled from follow-on schedule check
