[2024-02-07T09:08:45.510+0000] {taskinstance.py:1956} INFO - Dependencies all met for dep_context=non-requeueable deps ti=<TaskInstance: dag_complexe_xcom_fusion_table.create_table_1 scheduled__2024-01-07T00:00:00+00:00 [queued]>
[2024-02-07T09:08:45.632+0000] {taskinstance.py:1956} INFO - Dependencies all met for dep_context=requeueable deps ti=<TaskInstance: dag_complexe_xcom_fusion_table.create_table_1 scheduled__2024-01-07T00:00:00+00:00 [queued]>
[2024-02-07T09:08:45.647+0000] {taskinstance.py:2170} INFO - Starting attempt 1 of 2
[2024-02-07T09:08:46.237+0000] {taskinstance.py:2191} INFO - Executing <Task(PostgresOperator): create_table_1> on 2024-01-07 00:00:00+00:00
[2024-02-07T09:08:46.849+0000] {standard_task_runner.py:60} INFO - Started process 2379 to run task
[2024-02-07T09:08:47.442+0000] {standard_task_runner.py:87} INFO - Running: ['***', 'tasks', 'run', 'dag_complexe_xcom_fusion_table', 'create_table_1', 'scheduled__2024-01-07T00:00:00+00:00', '--job-id', '69', '--raw', '--subdir', 'DAGS_FOLDER/xcom_merging.py', '--cfg-path', '/tmp/tmp3fzr5_ut']
[2024-02-07T09:08:47.746+0000] {standard_task_runner.py:88} INFO - Job 69: Subtask create_table_1
[2024-02-07T09:08:53.754+0000] {task_command.py:423} INFO - Running <TaskInstance: dag_complexe_xcom_fusion_table.create_table_1 scheduled__2024-01-07T00:00:00+00:00 [running]> on host 4775ae97916b
[2024-02-07T09:09:05.477+0000] {taskinstance.py:2480} INFO - Exporting env vars: AIRFLOW_CTX_DAG_OWNER='vous' AIRFLOW_CTX_DAG_ID='dag_complexe_xcom_fusion_table' AIRFLOW_CTX_TASK_ID='create_table_1' AIRFLOW_CTX_EXECUTION_DATE='2024-01-07T00:00:00+00:00' AIRFLOW_CTX_TRY_NUMBER='1' AIRFLOW_CTX_DAG_RUN_ID='scheduled__2024-01-07T00:00:00+00:00'
[2024-02-07T09:09:05.698+0000] {sql.py:276} INFO - Executing: CREATE TABLE IF NOT EXISTS table_1 (id SERIAL PRIMARY KEY, name VARCHAR);
[2024-02-07T09:09:07.275+0000] {taskinstance.py:2698} ERROR - Task failed with exception
Traceback (most recent call last):
  File "/home/airflow/.local/lib/python3.8/site-packages/airflow/models/taskinstance.py", line 433, in _execute_task
    result = execute_callable(context=context, **execute_callable_kwargs)
  File "/home/airflow/.local/lib/python3.8/site-packages/airflow/providers/common/sql/operators/sql.py", line 277, in execute
    hook = self.get_db_hook()
  File "/home/airflow/.local/lib/python3.8/site-packages/airflow/providers/common/sql/operators/sql.py", line 188, in get_db_hook
    return self._hook
  File "/usr/local/lib/python3.8/functools.py", line 967, in __get__
    val = self.func(instance)
  File "/home/airflow/.local/lib/python3.8/site-packages/airflow/providers/common/sql/operators/sql.py", line 150, in _hook
    conn = BaseHook.get_connection(conn_id)
  File "/home/airflow/.local/lib/python3.8/site-packages/airflow/hooks/base.py", line 82, in get_connection
    conn = Connection.get_connection_from_secrets(conn_id)
  File "/home/airflow/.local/lib/python3.8/site-packages/airflow/models/connection.py", line 479, in get_connection_from_secrets
    raise AirflowNotFoundException(f"The conn_id `{conn_id}` isn't defined")
airflow.exceptions.AirflowNotFoundException: The conn_id `postgres_default` isn't defined
[2024-02-07T09:09:07.433+0000] {taskinstance.py:1138} INFO - Marking task as UP_FOR_RETRY. dag_id=dag_complexe_xcom_fusion_table, task_id=create_table_1, execution_date=20240107T000000, start_date=20240207T090845, end_date=20240207T090907
[2024-02-07T09:09:09.451+0000] {standard_task_runner.py:107} ERROR - Failed to execute job 69 for task create_table_1 (The conn_id `postgres_default` isn't defined; 2379)
[2024-02-07T09:09:09.900+0000] {local_task_job_runner.py:234} INFO - Task exited with return code 1
[2024-02-07T09:09:11.038+0000] {taskinstance.py:3280} INFO - 0 downstream tasks scheduled from follow-on schedule check
