[2024-02-06T22:36:44.411+0000] {taskinstance.py:1956} INFO - Dependencies all met for dep_context=non-requeueable deps ti=<TaskInstance: senegal_presidential_election_dag.query_and_return_value manual__2024-02-06T22:26:56.887233+00:00 [queued]>
[2024-02-06T22:36:44.427+0000] {taskinstance.py:1956} INFO - Dependencies all met for dep_context=requeueable deps ti=<TaskInstance: senegal_presidential_election_dag.query_and_return_value manual__2024-02-06T22:26:56.887233+00:00 [queued]>
[2024-02-06T22:36:44.427+0000] {taskinstance.py:2170} INFO - Starting attempt 3 of 4
[2024-02-06T22:36:44.454+0000] {taskinstance.py:2191} INFO - Executing <Task(PythonOperator): query_and_return_value> on 2024-02-06 22:26:56.887233+00:00
[2024-02-06T22:36:44.463+0000] {standard_task_runner.py:60} INFO - Started process 549 to run task
[2024-02-06T22:36:44.465+0000] {standard_task_runner.py:87} INFO - Running: ['***', 'tasks', 'run', 'senegal_presidential_election_dag', 'query_and_return_value', 'manual__2024-02-06T22:26:56.887233+00:00', '--job-id', '31', '--raw', '--subdir', 'DAGS_FOLDER/election_xcom.py', '--cfg-path', '/tmp/tmp4nirvwnc']
[2024-02-06T22:36:44.472+0000] {standard_task_runner.py:88} INFO - Job 31: Subtask query_and_return_value
[2024-02-06T22:36:44.559+0000] {task_command.py:423} INFO - Running <TaskInstance: senegal_presidential_election_dag.query_and_return_value manual__2024-02-06T22:26:56.887233+00:00 [running]> on host 4775ae97916b
[2024-02-06T22:36:44.673+0000] {taskinstance.py:2480} INFO - Exporting env vars: AIRFLOW_CTX_DAG_OWNER='el_mboup' AIRFLOW_CTX_DAG_ID='senegal_presidential_election_dag' AIRFLOW_CTX_TASK_ID='query_and_return_value' AIRFLOW_CTX_EXECUTION_DATE='2024-02-06T22:26:56.887233+00:00' AIRFLOW_CTX_TRY_NUMBER='3' AIRFLOW_CTX_DAG_RUN_ID='manual__2024-02-06T22:26:56.887233+00:00'
[2024-02-06T22:36:44.686+0000] {taskinstance.py:2698} ERROR - Task failed with exception
Traceback (most recent call last):
  File "/home/airflow/.local/lib/python3.8/site-packages/sqlalchemy/engine/base.py", line 1910, in _execute_context
    self.dialect.do_execute(
  File "/home/airflow/.local/lib/python3.8/site-packages/sqlalchemy/engine/default.py", line 736, in do_execute
    cursor.execute(statement, parameters)
psycopg2.errors.UndefinedTable: relation "senegal_presidential_candidates" does not exist
LINE 1: SELECT * FROM senegal_presidential_candidates WHERE satut_va...
                      ^


The above exception was the direct cause of the following exception:

Traceback (most recent call last):
  File "/home/airflow/.local/lib/python3.8/site-packages/airflow/models/taskinstance.py", line 433, in _execute_task
    result = execute_callable(context=context, **execute_callable_kwargs)
  File "/home/airflow/.local/lib/python3.8/site-packages/airflow/operators/python.py", line 199, in execute
    return_value = self.execute_callable()
  File "/home/airflow/.local/lib/python3.8/site-packages/airflow/operators/python.py", line 216, in execute_callable
    return self.python_callable(*self.op_args, **self.op_kwargs)
  File "/opt/airflow/dags/election_xcom.py", line 28, in query_table_and_return_value
    result = connection.execute(query).fetchall()
  File "/home/airflow/.local/lib/python3.8/site-packages/sqlalchemy/engine/base.py", line 1370, in execute
    return self._exec_driver_sql(
  File "/home/airflow/.local/lib/python3.8/site-packages/sqlalchemy/engine/base.py", line 1674, in _exec_driver_sql
    ret = self._execute_context(
  File "/home/airflow/.local/lib/python3.8/site-packages/sqlalchemy/engine/base.py", line 1953, in _execute_context
    self._handle_dbapi_exception(
  File "/home/airflow/.local/lib/python3.8/site-packages/sqlalchemy/engine/base.py", line 2134, in _handle_dbapi_exception
    util.raise_(
  File "/home/airflow/.local/lib/python3.8/site-packages/sqlalchemy/util/compat.py", line 211, in raise_
    raise exception
  File "/home/airflow/.local/lib/python3.8/site-packages/sqlalchemy/engine/base.py", line 1910, in _execute_context
    self.dialect.do_execute(
  File "/home/airflow/.local/lib/python3.8/site-packages/sqlalchemy/engine/default.py", line 736, in do_execute
    cursor.execute(statement, parameters)
sqlalchemy.exc.ProgrammingError: (psycopg2.errors.UndefinedTable) relation "senegal_presidential_candidates" does not exist
LINE 1: SELECT * FROM senegal_presidential_candidates WHERE satut_va...
                      ^

[SQL: SELECT * FROM senegal_presidential_candidates WHERE satut_validation = 'validée';]
(Background on this error at: https://sqlalche.me/e/14/f405)
[2024-02-06T22:36:44.698+0000] {taskinstance.py:1138} INFO - Marking task as UP_FOR_RETRY. dag_id=senegal_presidential_election_dag, task_id=query_and_return_value, execution_date=20240206T222656, start_date=20240206T223644, end_date=20240206T223644
[2024-02-06T22:36:44.718+0000] {standard_task_runner.py:107} ERROR - Failed to execute job 31 for task query_and_return_value ((psycopg2.errors.UndefinedTable) relation "senegal_presidential_candidates" does not exist
LINE 1: SELECT * FROM senegal_presidential_candidates WHERE satut_va...
                      ^

[SQL: SELECT * FROM senegal_presidential_candidates WHERE satut_validation = 'validée';]
(Background on this error at: https://sqlalche.me/e/14/f405); 549)
[2024-02-06T22:36:44.766+0000] {local_task_job_runner.py:234} INFO - Task exited with return code 1
[2024-02-06T22:36:44.794+0000] {taskinstance.py:3280} INFO - 0 downstream tasks scheduled from follow-on schedule check
