[2024-02-07T09:08:51.878+0000] {taskinstance.py:1956} INFO - Dependencies all met for dep_context=non-requeueable deps ti=<TaskInstance: dag_complexe_xcom_fusion_table.create_table_2 scheduled__2024-01-05T00:00:00+00:00 [queued]>
[2024-02-07T09:08:53.249+0000] {taskinstance.py:1956} INFO - Dependencies all met for dep_context=requeueable deps ti=<TaskInstance: dag_complexe_xcom_fusion_table.create_table_2 scheduled__2024-01-05T00:00:00+00:00 [queued]>
[2024-02-07T09:08:53.337+0000] {taskinstance.py:2170} INFO - Starting attempt 1 of 2
[2024-02-07T09:08:59.201+0000] {taskinstance.py:2191} INFO - Executing <Task(PostgresOperator): create_table_2> on 2024-01-05 00:00:00+00:00
[2024-02-07T09:09:00.058+0000] {standard_task_runner.py:60} INFO - Started process 2384 to run task
[2024-02-07T09:09:00.746+0000] {standard_task_runner.py:87} INFO - Running: ['***', 'tasks', 'run', 'dag_complexe_xcom_fusion_table', 'create_table_2', 'scheduled__2024-01-05T00:00:00+00:00', '--job-id', '74', '--raw', '--subdir', 'DAGS_FOLDER/xcom_merging.py', '--cfg-path', '/tmp/tmpe5mdr336']
[2024-02-07T09:09:01.615+0000] {standard_task_runner.py:88} INFO - Job 74: Subtask create_table_2
[2024-02-07T09:09:08.300+0000] {task_command.py:423} INFO - Running <TaskInstance: dag_complexe_xcom_fusion_table.create_table_2 scheduled__2024-01-05T00:00:00+00:00 [running]> on host 4775ae97916b
[2024-02-07T09:09:12.550+0000] {taskinstance.py:2480} INFO - Exporting env vars: AIRFLOW_CTX_DAG_OWNER='vous' AIRFLOW_CTX_DAG_ID='dag_complexe_xcom_fusion_table' AIRFLOW_CTX_TASK_ID='create_table_2' AIRFLOW_CTX_EXECUTION_DATE='2024-01-05T00:00:00+00:00' AIRFLOW_CTX_TRY_NUMBER='1' AIRFLOW_CTX_DAG_RUN_ID='scheduled__2024-01-05T00:00:00+00:00'
[2024-02-07T09:09:12.670+0000] {sql.py:276} INFO - Executing: CREATE TABLE IF NOT EXISTS table_2 (id SERIAL PRIMARY KEY, age INT);
[2024-02-07T09:09:13.193+0000] {taskinstance.py:2698} ERROR - Task failed with exception
Traceback (most recent call last):
  File "/home/airflow/.local/lib/python3.8/site-packages/airflow/models/taskinstance.py", line 433, in _execute_task
    result = execute_callable(context=context, **execute_callable_kwargs)
  File "/home/airflow/.local/lib/python3.8/site-packages/airflow/providers/common/sql/operators/sql.py", line 277, in execute
    hook = self.get_db_hook()
  File "/home/airflow/.local/lib/python3.8/site-packages/airflow/providers/common/sql/operators/sql.py", line 188, in get_db_hook
    return self._hook
  File "/usr/local/lib/python3.8/functools.py", line 967, in __get__
    val = self.func(instance)
  File "/home/airflow/.local/lib/python3.8/site-packages/airflow/providers/common/sql/operators/sql.py", line 150, in _hook
    conn = BaseHook.get_connection(conn_id)
  File "/home/airflow/.local/lib/python3.8/site-packages/airflow/hooks/base.py", line 82, in get_connection
    conn = Connection.get_connection_from_secrets(conn_id)
  File "/home/airflow/.local/lib/python3.8/site-packages/airflow/models/connection.py", line 479, in get_connection_from_secrets
    raise AirflowNotFoundException(f"The conn_id `{conn_id}` isn't defined")
airflow.exceptions.AirflowNotFoundException: The conn_id `postgres_default` isn't defined
[2024-02-07T09:09:13.588+0000] {taskinstance.py:1138} INFO - Marking task as UP_FOR_RETRY. dag_id=dag_complexe_xcom_fusion_table, task_id=create_table_2, execution_date=20240105T000000, start_date=20240207T090851, end_date=20240207T090913
[2024-02-07T09:09:13.881+0000] {standard_task_runner.py:107} ERROR - Failed to execute job 74 for task create_table_2 (The conn_id `postgres_default` isn't defined; 2384)
[2024-02-07T09:09:14.151+0000] {local_task_job_runner.py:234} INFO - Task exited with return code 1
[2024-02-07T09:09:15.071+0000] {taskinstance.py:3280} INFO - 0 downstream tasks scheduled from follow-on schedule check
